import java.util.*;

class Exception3
{
    public static void main(String Arg[])
    {
        try
        {
       
        }
        catch(ArrayIndexOutOfBoundsException obj)
        {
            
        }
        catch(ArithematicException obj)
        {
        
        }
        catch(Exception obj)
        {

        }
        finally
        {
            System.out.println("Inside finally block");
        }
    }
}